Workbook

Sheet Instructions
A1: Day 095 — HR Analytics
A3: Author | B3: Saloni Tiwari
A4: Programme | B4: IIT Madras BS Degree — Diploma Level
A5: Day | B5: 095
A6: Topic | B6: HR Analytics
A8: Workflow
A9: Raw HR Data → Data Quality Check → Cleaning → Employee Analysis → Department/Role/Salary/Attrition Analysis → KPIs → Pivot Analysis → Charts → Business Insights

Sheet Raw_HR_Data
A1: Raw HR Data — Practice Dataset
A2: Intentional issues are included for cleaning practice.
A4: Employee_ID | B4: Joining_Date | C4: Employee_Name | D4: Age | E4: Department | F4: Job_Role | G4: Education | H4: Location | I4: Experience_Years | J4: Monthly_Salary | K4: Employment_Type | L4: Employee_Status | M4: Attrition
A5: E001 | B5: 45794 | C5: Employee 1 | D5: 36 | E5: Sales | F5: Sales Executive | G5: Graduate | H5: Delhi | I5: 17 | J5: 87918 | K5: Full-Time | L5: Resigned | M5: Yes
A6: E002 | B6: 45708 | C6: Employee 2 | D6: 39 | E6: Finance | F6: Financial Analyst | G6: Graduate | H6: Patna | I6: 2 | J6: 54532 | K6: Part-Time | L6: Active | M6: No
A7: E003 | B7: 45820 | C7: Employee 3 | D7: 26 | E7: HR | F7: HR Executive | G7: Graduate | H7: Bengaluru | I7: 8 | J7: 64340 | K7: Part-Time | L7: Active | M7: No
A8: E004 | B8: 45922 | C8: Employee 4 | D8: 37 | E8: IT | F8: Software Analyst | G8: Graduate | H8: delhi | I8: 5 | J8: 82342 | K8: Full-Time | L8: Active | M8: No
A9: E005 | B9: 45677 | C9: Employee 5 | D9: 21 | E9: Marketing | F9: Marketing Executive | G9: Postgraduate | H9: Kolkata | I9: 11 | J9: 76196 | K9: Part-Time | L9: Active | M9: No
A10: E006 | B10: 46103 | C10: Employee 6 | D10: 40 | E10: Operations | F10: Operations Executive | G10: Postgraduate | H10: Patna | I10: 9 | K10: Full-Time | L10: Active | M10: No
A11: E007 | B11: 45677 | C11: Employee 7 | D11: 27 | E11: Sales | F11: Sales Executive | G11: Postgraduate | H11: Delhi | I11: 2 | J11: 51225 | K11: Part-Time | L11: Active | M11: No
A12: E008 | B12: 46066 | C12: Employee 8 | D12: 43 | E12: Finance | F12: software analyst | G12: Postgraduate | H12: Delhi | I12: 18 | J12: 92704 | K12: Full-Time | L12: Resigned | M12: Yes
A13: E009 | B13: 45994 | C13: Employee 9 | D13: 30 | E13: HR | F13: HR Executive | G13: Postgraduate | H13: Kolkata | I13: 14 | J13: 80520 | K13: Full-Time | L13: Active | M13: No
A14: E010 | B14: 45778 | C14: Employee 10 | D14: 26 | E14: IT | F14: Software Analyst | G14: Graduate | H14: Patna | I14: 8 | J14: 82311 | K14: Full-Time | L14: Active | M14: No
A15: E011 | B15: 45684 | C15: Employee 11 | D15: 32 | E15: Marketing | F15: Marketing Executive | G15: Postgraduate | H15: Delhi | I15: 6 | J15: 63306 | K15: Part-Time | L15: Resigned | M15: Yes
A16: E012 | B16: 45686 | C16: Employee 12 | D16: 40 | E16: Operations | F16: Operations Executive | G16: Postgraduate | H16: Kolkata | I16: 7 | J16: 56552 | K16: Full-Time | L16: active | M16: No
A17: E013 | B17: 46041 | C17: Employee 13 | D17: 34 | E17: Sales | F17: Sales Executive | G17: Postgraduate | H17: Patna | I17: 0 | J17: 41807 | K17: Part-Time | L17: Active | M17: No
A18: E014 | B18: 46183 | C18: Employee 14 | E18: Finance | F18: Financial Analyst | G18: Graduate | H18: Mumbai | I18: 14 | J18: 87486 | K18: Full-Time | L18: Active | M18: No
A19: E015 | B19: 45807 | C19: Employee 15 | D19: 31 | E19: HR | F19: HR Executive | G19: Graduate | H19: Delhi | I19: 10 | J19: 66637 | K19: Full-Time | L19: Active | M19: No
A20: E016 | B20: 45665 | C20: Employee 16 | D20: 41 | E20: IT | F20: Software Analyst | G20: Postgraduate | H20: Kolkata | I20: 8 | J20: 83626 | K20: Part-Time | L20: Active | M20: yes
A21: E017 | B21: 46055 | C21: Employee 17 | D21: 45 | E21: Marketing | F21: Marketing Executive | G21: Postgraduate | H21: Delhi | I21: 6 | J21: 61357 | K21: Full-Time | L21: Active | M21: No
A22: E018 | B22: 45800 | C22: Employee 18 | D22: 24 | E22: Operations | F22: Operations Executive | G22: Postgraduate | H22: Kolkata | I22: 9 | J22: 64970 | K22: Full-Time | L22: On Leave | M22: No
A23: E019 | B23: 46124 | C23: Employee 19 | D23: 42 | E23: Sales | F23: Sales Executive | G23: Postgraduate | H23: Kolkata | I23: 2 | J23: 48218 | K23: Part-Time | L23: Active | M23: No
A24: E020 | B24: 45717 | C24: Employee 20 | D24: 43 | E24: Finance | F24: Financial Analyst | G24: Postgraduate | H24: Bengaluru | I24: 10 | J24: 79678 | K24: Full-Time | L24: On Leave | M24: No
A25: E021 | B25: 45760 | C25: Employee 21 | D25: 21 | E25: HR | F25: HR Executive | G25: Graduate | H25: Mumbai | J25: 50764 | K25: Full-Time | L25: On Leave | M25: No
A26: E022 | B26: 46138 | C26: Employee 22 | D26: 43 | E26: IT | F26: Software Analyst | G26: Postgraduate | H26: Bengaluru | I26: 7 | J26: 77636 | K26: Part-Time | L26: Active | M26: No
A27: E023 | B27: 46110 | C27: Employee 23 | D27: 27 | E27: Marketing | F27: Marketing Executive | G27: Graduate | H27: Kolkata | I27: 9 | J27: 65660 | K27: Part-Time | L27: Active | M27: No
A28: E024 | B28: 45867 | C28: Employee 24 | D28: 26 | E28: Operations | F28: Operations Executive | G28: Graduate | H28: Patna | I28: 2 | J28: 47002 | K28: Full-Time | L28: Active | M28: No
A29: E025 | B29: 46165 | C29: Employee 25 | D29: 42 | E29: Sales | F29: Sales Executive | G29: Graduate | H29: Bengaluru | I29: 9 | J29: 62888 | K29: Full-Time | L29: Active | M29: No
A30: E026 | B30: 45735 | C30: Employee 26 | D30: 44 | E30: Finance | F30: Financial Analyst | G30: Postgraduate | H30: Bengaluru | I30: 6 | J30: 64238 | K30: Part-Time | L30: Resigned | M30: Yes
A31: E027 | B31: 45950 | C31: Employee 27 | D31: 23 | F31: HR Executive | G31: Postgraduate | H31: Kolkata | I31: 18 | J31: 92423 | K31: Full-Time | L31: Active | M31: No
A32: E028 | B32: 45890 | C32: Employee 28 | D32: 21 | E32: IT | F32: Software Analyst | G32: Postgraduate | H32: Delhi | I32: 7 | J32: 79969 | K32: Full-Time | L32: Active | M32: No
A33: E029 | B33: 45778 | C33: Employee 29 | D33: 23 | E33: Marketing | F33: Marketing Executive | G33: Postgraduate | H33: Kolkata | I33: 16 | J33: 88475 | K33: Full-Time | L33: Resigned | M33: Yes
A34: E030 | B34: 45715 | C34: Employee 30 | D34: 26 | E34: Operations | F34: Operations Executive | G34: Graduate | H34: Mumbai | I34: -2 | J34: 52721 | K34: Part-Time | L34: Resigned | M34: Yes
A35: E031 | B35: 45674 | C35: Employee 31 | D35: 45 | E35: Sales | F35: Sales Executive | G35: Postgraduate | H35: Kolkata | I35: 17 | J35: 82400 | K35: Part-Time | L35: Active | M35: No
A36: E032 | B36: 46020 | C36: Employee 32 | D36: 23 | E36: Finance | F36: Financial Analyst | G36: Postgraduate | H36: Delhi | I36: 11 | J36: 73307 | K36: Full-Time | L36: Active | M36: No
A37: E033 | B37: 45874 | C37: Employee 33 | D37: 39 | E37: HR | F37: HR Executive | G37: Postgraduate | H37: Delhi | I37: 17 | J37: 86377 | K37: Full-Time | L37: Active | M37: No
A38: E034 | B38: 45861 | C38: Employee 34 | D38: 23 | E38: IT | F38: Software Analyst | G38: Graduate | H38: Mumbai | I38: 14 | J38: 95899 | K38: Part-Time | L38: Active | M38: No
A39: E035 | B39: 45842 | C39: Employee 35 | D39: 22 | E39: Marketing | F39: Marketing Executive | G39: Postgraduate | H39: Delhi | I39: 14 | J39: 84486 | K39: Full-Time | L39: Active | M39: No
A40: E036 | B40: 45972 | C40: Employee 36 | D40: 23 | E40: Operations | F40: Operations Executive | G40: Postgraduate | H40: Bengaluru | I40: 4 | J40: 46866 | K40: Full-Time | L40: On Leave | M40: No
A41: E037 | B41: 46063 | C41: Employee 37 | D41: 41 | E41: Sales | F41: Sales Executive | G41: Postgraduate | H41: Bengaluru | I41: 9 | J41: 61642 | K41: Full-Time | L41: On Leave | M41: No
...

Sheet Data_Quality_Check
A1: HR Data Quality Check
A4: Check | B4: Result | C4: Rule | D4: Status
A5: Total Records | B5: 61 | C5: Expected 61 raw rows including one duplicate | D5: Review
A6: Missing Age | B6: =COUNTBLANK(Raw_HR_Data!D5:D65) | C6: Should be reviewed | D6: Review
A7: Missing Department | B7: =COUNTBLANK(Raw_HR_Data!E5:E65) | C7: Should be reviewed | D7: Review
A8: Missing Salary | B8: =COUNTBLANK(Raw_HR_Data!J5:J65) | C8: Should be reviewed | D8: Review
A9: Negative Experience | B9: =COUNTIF(Raw_HR_Data!I5:I65,"<0") | C9: Should be 0 after cleaning | D9: Review
A10: Duplicate Rows | B10: 1 | C10: Remove exact duplicate | D10: Review
A11: Text Consistency | B11: Review manually | C11: Trim and standardise case | D11: Review

Sheet HR_Cleaning
A1: HR Data Cleaning
A4: Issue | B4: Cleaning Action | C4: Example
A5: Extra spaces | B5: Trim text | C5: ' Sales ' → 'Sales'
A6: Inconsistent case | B6: Standardise text | C6: 'software analyst' → 'Software Analyst'
A7: Missing Age | B7: Replace with documented practice value | C7: Validate before use
A8: Missing Department | B8: Replace with documented practice value | C8: Validate before use
A9: Missing Salary | B9: Replace with documented practice value | C9: Validate before use
A10: Missing Experience | B10: Replace with documented practice value | C10: Validate before use
A11: Negative Experience | B11: Correct after validation | C11: Experience cannot be negative
A12: Invalid numeric text | B12: Convert to numeric | C12: 'N/A' → missing
A13: Duplicate record | B13: Remove exact duplicate | C13: Keep one record

Sheet Cleaned_HR_Data
A1: Cleaned HR Data
A4: Employee_ID | B4: Joining_Date | C4: Employee_Name | D4: Age | E4: Department | F4: Job_Role | G4: Education | H4: Location | I4: Experience_Years | J4: Monthly_Salary | K4: Employment_Type | L4: Employee_Status | M4: Attrition
A5: E001 | B5: 45794 | C5: Employee 1 | D5: 36 | E5: Sales | F5: Sales Executive | G5: Graduate | H5: Delhi | I5: 17 | J5: 87918 | K5: Full-Time | L5: Resigned | M5: Yes
A6: E002 | B6: 45708 | C6: Employee 2 | D6: 39 | E6: Finance | F6: Financial Analyst | G6: Graduate | H6: Patna | I6: 2 | J6: 54532 | K6: Part-Time | L6: Active | M6: No
A7: E003 | B7: 45820 | C7: Employee 3 | D7: 26 | E7: Hr | F7: Hr Executive | G7: Graduate | H7: Bengaluru | I7: 8 | J7: 64340 | K7: Part-Time | L7: Active | M7: No
A8: E004 | B8: 45922 | C8: Employee 4 | D8: 37 | E8: It | F8: Software Analyst | G8: Graduate | H8: Patna | I8: 5 | J8: 82342 | K8: Full-Time | L8: Active | M8: No
A9: E005 | B9: 45677 | C9: Employee 5 | D9: 21 | E9: Sales | F9: Marketing Executive | G9: Postgraduate | H9: Kolkata | I9: 11 | J9: 76196 | K9: Part-Time | L9: Active | M9: No
A10: E006 | B10: 46103 | C10: Employee 6 | D10: 40 | E10: Operations | F10: Operations Executive | G10: Postgraduate | H10: Patna | I10: 9 | J10: 63580 | K10: Full-Time | L10: Active | M10: No
A11: E007 | B11: 45677 | C11: Employee 7 | D11: 27 | E11: Sales | F11: Sales Executive | G11: Postgraduate | H11: Delhi | I11: 2 | J11: 51225 | K11: Part-Time | L11: Active | M11: No
A12: E008 | B12: 46066 | C12: Employee 8 | D12: 43 | E12: Finance | F12: Financial Analyst | G12: Postgraduate | H12: Delhi | I12: 18 | J12: 92704 | K12: Full-Time | L12: Resigned | M12: Yes
A13: E009 | B13: 45994 | C13: Employee 9 | D13: 30 | E13: Hr | F13: Hr Executive | G13: Postgraduate | H13: Kolkata | I13: 14 | J13: 80520 | K13: Full-Time | L13: Active | M13: No
A14: E010 | B14: 45778 | C14: Employee 10 | D14: 26 | E14: It | F14: Software Analyst | G14: Graduate | H14: Patna | I14: 8 | J14: 46000 | K14: Full-Time | L14: Active | M14: No
A15: E011 | B15: 45684 | C15: Employee 11 | D15: 32 | E15: Marketing | F15: Marketing Executive | G15: Postgraduate | H15: Delhi | I15: 6 | J15: 63306 | K15: Part-Time | L15: Resigned | M15: Yes
A16: E012 | B16: 45686 | C16: Employee 12 | D16: 40 | E16: Operations | F16: Software Analyst | G16: Postgraduate | H16: Kolkata | I16: 7 | J16: 56552 | K16: Full-Time | L16: On Leave | M16: No
... A64: E060 | B64: 46038 | C64: Employee 60 | D64: 26 | E64: Operations | F64: Operations Executive | G64: Graduate | H64: Kolkata | I64: 4 | J64: 52947 | K64: Part-Time | L64: Resigned | M64: Yes

Sheet Employee_Summary
A1: Employee Summary
A4: Metric | B4: Value
A5: Total Employees | B5: =COUNTA(Cleaned_HR_Data!A5:A64)
A6: Average Age | B6: =AVERAGE(Cleaned_HR_Data!D5:D64)
A7: Average Experience (Years) | B7: =AVERAGE(Cleaned_HR_Data!I5:I64)
A8: Average Monthly Salary | B8: =AVERAGE(Cleaned_HR_Data!J5:J64)
A9: Total Monthly Salary Cost | B9: =SUM(Cleaned_HR_Data!J5:J64)
A10: Active Employees | B10: =COUNTIF(Cleaned_HR_Data!L5:L64,"Active")
A11: Attrition Count | B11: =COUNTIF(Cleaned_HR_Data!M5:M64,"Yes")

Sheet Department_Analysis
A1: Department Analysis
A4: Department | B4: Employee_Count | C4: Average_Salary | D4: Total_Salary | E4: Average_Experience | F4: Attrition_Count | G4: Attrition_Rate_%
A5: Sales | B5: =COUNTIF(Cleaned_HR_Data!E5:E64,A5) | C5: =AVERAGEIF(Cleaned_HR_Data!E5:E64,A5,Cleaned_HR_Data!J5:J64) | D5: =SUMIF(Cleaned_HR_Data!E5:E64,A5,Cleaned_HR_Data!J5:J64) | E5: =AVERAGEIF(Cleaned_HR_Data!E5:E64,A5,Cleaned_HR_Data!I5:I64) | F5: =COUNTIFS(Cleaned_HR_Data!E5:E64,A5,Cleaned_HR_Data!M5:M64,"Yes") | G5: =IF(B5=0,0,F5/B5*100)
A6: Finance | B6: =COUNTIF(Cleaned_HR_Data!E5:E64,A6) | C6: =AVERAGEIF(Cleaned_HR_Data!E5:E64,A6,Cleaned_HR_Data!J5:J64) | D6: =SUMIF(Cleaned_HR_Data!E5:E64,A6,Cleaned_HR_Data!J5:J64) | E6: =AVERAGEIF(Cleaned_HR_Data!E5:E64,A6,Cleaned_HR_Data!I5:I64) | F6: =COUNTIFS(Cleaned_HR_Data!E5:E64,A6,Cleaned_HR_Data!M5:M64,"Yes") | G6: =IF(B6=0,0,F6/B6*100)
A7: HR | B7: =COUNTIF(Cleaned_HR_Data!E5:E64,A7) | C7: =AVERAGEIF(Cleaned_HR_Data!E5:E64,A7,Cleaned_HR_Data!J5:J64) | D7: =SUMIF(Cleaned_HR_Data!E5:E64,A7,Cleaned_HR_Data!J5:J64) | E7: =AVERAGEIF(Cleaned_HR_Data!E5:E64,A7,Cleaned_HR_Data!I5:I64) | F7: =COUNTIFS(Cleaned_HR_Data!E5:E64,A7,Cleaned_HR_Data!M5:M64,"Yes") | G7: =IF(B7=0,0,F7/B7*100)
A8: IT | B8: =COUNTIF(Cleaned_HR_Data!E5:E64,A8) | C8: =AVERAGEIF(Cleaned_HR_Data!E5:E64,A8,Cleaned_HR_Data!J5:J64) | D8: =SUMIF(Cleaned_HR_Data!E5:E64,A8,Cleaned_HR_Data!J5:J64) | E8: =AVERAGEIF(Cleaned_HR_Data!E5:E64,A8,Cleaned_HR_Data!I5:I64) | F8: =COUNTIFS(Cleaned_HR_Data!E5:E64,A8,Cleaned_HR_Data!M5:M64,"Yes") | G8: =IF(B8=0,0,F8/B8*100)
A9: Marketing | B9: =COUNTIF(Cleaned_HR_Data!E5:E64,A9) | C9: =AVERAGEIF(Cleaned_HR_Data!E5:E64,A9,Cleaned_HR_Data!J5:J64) | D9: =SUMIF(Cleaned_HR_Data!E5:E64,A9,Cleaned_HR_Data!J5:J64) | E9: =AVERAGEIF(Cleaned_HR_Data!E5:E64,A9,Cleaned_HR_Data!I5:I64) | F9: =COUNTIFS(Cleaned_HR_Data!E5:E64,A9,Cleaned_HR_Data!M5:M64,"Yes") | G9: =IF(B9=0,0,F9/B9*100)
A10: Operations | B10: =COUNTIF(Cleaned_HR_Data!E5:E64,A10) | C10: =AVERAGEIF(Cleaned_HR_Data!E5:E64,A10,Cleaned_HR_Data!J5:J64) | D10: =SUMIF(Cleaned_HR_Data!E5:E64,A10,Cleaned_HR_Data!J5:J64) | E10: =AVERAGEIF(Cleaned_HR_Data!E5:E64,A10,Cleaned_HR_Data!I5:I64) | F10: =COUNTIFS(Cleaned_HR_Data!E5:E64,A10,Cleaned_HR_Data!M5:M64,"Yes") | G10: =IF(B10=0,0,F10/B10*100)

Sheet Job_Role_Analysis
A1: Job Role Analysis
A4: Job_Role | B4: Employee_Count | C4: Average_Salary | D4: Total_Salary | E4: Average_Experience
A5: Sales Executive | B5: =COUNTIF(Cleaned_HR_Data!F5:F64,A5) | C5: =AVERAGEIF(Cleaned_HR_Data!F5:F64,A5,Cleaned_HR_Data!J5:J64) | D5: =SUMIF(Cleaned_HR_Data!F5:F64,A5,Cleaned_HR_Data!J5:J64) | E5: =AVERAGEIF(Cleaned_HR_Data!F5:F64,A5,Cleaned_HR_Data!I5:I64)
A6: Financial Analyst | B6: =COUNTIF(Cleaned_HR_Data!F5:F64,A6) | C6: =AVERAGEIF(Cleaned_HR_Data!F5:F64,A6,Cleaned_HR_Data!J5:J64) | D6: =SUMIF(Cleaned_HR_Data!F5:F64,A6,Cleaned_HR_Data!J5:J64) | E6: =AVERAGEIF(Cleaned_HR_Data!F5:F64,A6,Cleaned_HR_Data!I5:I64)
A7: HR Executive | B7: =COUNTIF(Cleaned_HR_Data!F5:F64,A7) | C7: =AVERAGEIF(Cleaned_HR_Data!F5:F64,A7,Cleaned_HR_Data!J5:J64) | D7: =SUMIF(Cleaned_HR_Data!F5:F64,A7,Cleaned_HR_Data!J5:J64) | E7: =AVERAGEIF(Cleaned_HR_Data!F5:F64,A7,Cleaned_HR_Data!I5:I64)
A8: Software Analyst | B8: =COUNTIF(Cleaned_HR_Data!F5:F64,A8) | C8: =AVERAGEIF(Cleaned_HR_Data!F5:F64,A8,Cleaned_HR_Data!J5:J64) | D8: =SUMIF(Cleaned_HR_Data!F5:F64,A8,Cleaned_HR_Data!J5:J64) | E8: =AVERAGEIF(Cleaned_HR_Data!F5:F64,A8,Cleaned_HR_Data!I5:I64)
A9: Marketing Executive | B9: =COUNTIF(Cleaned_HR_Data!F5:F64,A9) | C9: =AVERAGEIF(Cleaned_HR_Data!F5:F64,A9,Cleaned_HR_Data!J5:J64) | D9: =SUMIF(Cleaned_HR_Data!F5:F64,A9,Cleaned_HR_Data!J5:J64) | E9: =AVERAGEIF(Cleaned_HR_Data!F5:F64,A9,Cleaned_HR_Data!I5:I64)
A10: Operations Executive | B10: =COUNTIF(Cleaned_HR_Data!F5:F64,A10) | C10: =AVERAGEIF(Cleaned_HR_Data!F5:F64,A10,Cleaned_HR_Data!J5:J64) | D10: =SUMIF(Cleaned_HR_Data!F5:F64,A10,Cleaned_HR_Data!J5:J64) | E10: =AVERAGEIF(Cleaned_HR_Data!F5:F64,A10,Cleaned_HR_Data!I5:I64)

Sheet Salary_Analysis
A1: Salary Analysis
A4: Department | B4: Average_Salary | C4: Minimum_Salary | D4: Maximum_Salary | E4: Total_Salary
A5: Sales | B5: =AVERAGEIF(Cleaned_HR_Data!E5:E64,A5,Cleaned_HR_Data!J5:J64) | C5: =MINIFS(Cleaned_HR_Data!J5:J64,Cleaned_HR_Data!E5:E64,A5) | D5: =MAXIFS(Cleaned_HR_Data!J5:J64,Cleaned_HR_Data!E5:E64,A5) | E5: =SUMIF(Cleaned_HR_Data!E5:E64,A5,Cleaned_HR_Data!J5:J64)
A6: Finance | B6: =AVERAGEIF(Cleaned_HR_Data!E5:E64,A6,Cleaned_HR_Data!J5:J64) | C6: =MINIFS(Cleaned_HR_Data!J5:J64,Cleaned_HR_Data!E5:E64,A6) | D6: =MAXIFS(Cleaned_HR_Data!J5:J64,Cleaned_HR_Data!E5:E64,A6) | E6: =SUMIF(Cleaned_HR_Data!E5:E64,A6,Cleaned_HR_Data!J5:J64)
A7: HR | B7: =AVERAGEIF(Cleaned_HR_Data!E5:E64,A7,Cleaned_HR_Data!J5:J64) | C7: =MINIFS(Cleaned_HR_Data!J5:J64,Cleaned_HR_Data!E5:E64,A7) | D7: =MAXIFS(Cleaned_HR_Data!J5:J64,Cleaned_HR_Data!E5:E64,A7) | E7: =SUMIF(Cleaned_HR_Data!E5:E64,A7,Cleaned_HR_Data!J5:J64)
A8: IT | B8: =AVERAGEIF(Cleaned_HR_Data!E5:E64,A8,Cleaned_HR_Data!J5:J64) | C8: =MINIFS(Cleaned_HR_Data!J5:J64,Cleaned_HR_Data!E5:E64,A8) | D8: =MAXIFS(Cleaned_HR_Data!J5:J64,Cleaned_HR_Data!E5:E64,A8) | E8: =SUMIF(Cleaned_HR_Data!E5:E64,A8,Cleaned_HR_Data!J5:J64)
A9: Marketing | B9: =AVERAGEIF(Cleaned_HR_Data!E5:E64,A9,Cleaned_HR_Data!J5:J64) | C9: =MINIFS(Cleaned_HR_Data!J5:J64,Cleaned_HR_Data!E5:E64,A9) | D9: =MAXIFS(Cleaned_HR_Data!J5:J64,Cleaned_HR_Data!E5:E64,A9) | E9: =SUMIF(Cleaned_HR_Data!E5:E64,A9,Cleaned_HR_Data!J5:J64)
A10: Operations | B10: =AVERAGEIF(Cleaned_HR_Data!E5:E64,A10,Cleaned_HR_Data!J5:J64) | C10: =MINIFS(Cleaned_HR_Data!J5:J64,Cleaned_HR_Data!E5:E64,A10) | D10: =MAXIFS(Cleaned_HR_Data!J5:J64,Cleaned_HR_Data!E5:E64,A10) | E10: =SUMIF(Cleaned_HR_Data!E5:E64,A10,Cleaned_HR_Data!J5:J64)

Sheet Attrition_Analysis
A1: Attrition Analysis
A4: Department | B4: Employees | C4: Attrition_Count | D4: Attrition_Rate_%
A5: Sales | B5: =COUNTIF(Cleaned_HR_Data!E5:E64,A5) | C5: =COUNTIFS(Cleaned_HR_Data!E5:E64,A5,Cleaned_HR_Data!M5:M64,"Yes") | D5: =IF(B5=0,0,C5/B5*100)
A6: Finance | B6: =COUNTIF(Cleaned_HR_Data!E5:E64,A6) | C6: =COUNTIFS(Cleaned_HR_Data!E5:E64,A6,Cleaned_HR_Data!M5:M64,"Yes") | D6: =IF(B6=0,0,C6/B6*100)
A7: HR | B7: =COUNTIF(Cleaned_HR_Data!E5:E64,A7) | C7: =COUNTIFS(Cleaned_HR_Data!E5:E64,A7,Cleaned_HR_Data!M5:M64,"Yes") | D7: =IF(B7=0,0,C7/B7*100)
A8: IT | B8: =COUNTIF(Cleaned_HR_Data!E5:E64,A8) | C8: =COUNTIFS(Cleaned_HR_Data!E5:E64,A8,Cleaned_HR_Data!M5:M64,"Yes") | D8: =IF(B8=0,0,C8/B8*100)
A9: Marketing | B9: =COUNTIF(Cleaned_HR_Data!E5:E64,A9) | C9: =COUNTIFS(Cleaned_HR_Data!E5:E64,A9,Cleaned_HR_Data!M5:M64,"Yes") | D9: =IF(B9=0,0,C9/B9*100)
A10: Operations | B10: =COUNTIF(Cleaned_HR_Data!E5:E64,A10) | C10: =COUNTIFS(Cleaned_HR_Data!E5:E64,A10,Cleaned_HR_Data!M5:M64,"Yes") | D10: =IF(B10=0,0,C10/B10*100)

Sheet Monthly_HR
A1: Monthly HR Analysis
A4: Month | B4: Employee_Records | C4: New_Joiners | D4: Attrition_Count | E4: Total_Monthly_Salary
A5: 45658 | B5: =COUNTIFS(Cleaned_HR_Data!B5:B64,">="&A5,Cleaned_HR_Data!B5:B64,"<"&EDATE(A5,1)) | C5: =COUNTIFS(Cleaned_HR_Data!B5:B64,">="&A5,Cleaned_HR_Data!B5:B64,"<"&EDATE(A5,1)) | D5: 0 | E5: =SUMIFS(Cleaned_HR_Data!J5:J64,Cleaned_HR_Data!B5:B64,">="&A5,Cleaned_HR_Data!B5:B64,"<"&EDATE(A5,1))
A6: 45689 | B6: =COUNTIFS(Cleaned_HR_Data!B5:B64,">="&A6,Cleaned_HR_Data!B5:B64,"<"&EDATE(A6,1)) | C6: =COUNTIFS(Cleaned_HR_Data!B5:B64,">="&A6,Cleaned_HR_Data!B5:B64,"<"&EDATE(A6,1)) | D6: 0 | E6: =SUMIFS(Cleaned_HR_Data!J5:J64,Cleaned_HR_Data!B5:B64,">="&A6,Cleaned_HR_Data!B5:B64,"<"&EDATE(A6,1))
A7: 45717 | B7: =COUNTIFS(Cleaned_HR_Data!B5:B64,">="&A7,Cleaned_HR_Data!B5:B64,"<"&EDATE(A7,1)) | C7: =COUNTIFS(Cleaned_HR_Data!B5:B64,">="&A7,Cleaned_HR_Data!B5:B64,"<"&EDATE(A7,1)) | D7: 0 | E7: =SUMIFS(Cleaned_HR_Data!J5:J64,Cleaned_HR_Data!B5:B64,">="&A7,Cleaned_HR_Data!B5:B64,"<"&EDATE(A7,1))
A8: 45748 | B8: =COUNTIFS(Cleaned_HR_Data!B5:B64,">="&A8,Cleaned_HR_Data!B5:B64,"<"&EDATE(A8,1)) | C8: =COUNTIFS(Cleaned_HR_Data!B5:B64,">="&A8,Cleaned_HR_Data!B5:B64,"<"&EDATE(A8,1)) | D8: 0 | E8: =SUMIFS(Cleaned_HR_Data!J5:J64,Cleaned_HR_Data!B5:B64,">="&A8,Cleaned_HR_Data!B5:B64,"<"&EDATE(A8,1))
A9: 45778 | B9: =COUNTIFS(Cleaned_HR_Data!B5:B64,">="&A9,Cleaned_HR_Data!B5:B64,"<"&EDATE(A9,1)) | C9: =COUNTIFS(Cleaned_HR_Data!B5:B64,">="&A9,Cleaned_HR_Data!B5:B64,"<"&EDATE(A9,1)) | D9: 0 | E9: =SUMIFS(Cleaned_HR_Data!J5:J64,Cleaned_HR_Data!B5:B64,">="&A9,Cleaned_HR_Data!B5:B64,"<"&EDATE(A9,1))
A10: 45809 | B10: =COUNTIFS(Cleaned_HR_Data!B5:B64,">="&A10,Cleaned_HR_Data!B5:B64,"<"&EDATE(A10,1)) | C10: =COUNTIFS(Cleaned_HR_Data!B5:B64,">="&A10,Cleaned_HR_Data!B5:B64,"<"&EDATE(A10,1)) | D10: 0 | E10: =SUMIFS(Cleaned_HR_Data!J5:J64,Cleaned_HR_Data!B5:B64,">="&A10,Cleaned_HR_Data!B5:B64,"<"&EDATE(A10,1))
A11: 45839 | B11: =COUNTIFS(Cleaned_HR_Data!B5:B64,">="&A11,Cleaned_HR_Data!B5:B64,"<"&EDATE(A11,1)) | C11: =COUNTIFS(Cleaned_HR_Data!B5:B64,">="&A11,Cleaned_HR_Data!B5:B64,"<"&EDATE(A11,1)) | D11: 0 | E11: =SUMIFS(Cleaned_HR_Data!J5:J64,Cleaned_HR_Data!B5:B64,">="&A11,Cleaned_HR_Data!B5:B64,"<"&EDATE(A11,1))
A12: 45870 | B12: =COUNTIFS(Cleaned_HR_Data!B5:B64,">="&A12,Cleaned_HR_Data!B5:B64,"<"&EDATE(A12,1)) | C12: =COUNTIFS(Cleaned_HR_Data!B5:B64,">="&A12,Cleaned_HR_Data!B5:B64,"<"&EDATE(A12,1)) | D12: 0 | E12: =SUMIFS(Cleaned_HR_Data!J5:J64,Cleaned_HR_Data!B5:B64,">="&A12,Cleaned_HR_Data!B5:B64,"<"&EDATE(A12,1))
A13: 45901 | B13: =COUNTIFS(Cleaned_HR_Data!B5:B64,">="&A13,Cleaned_HR_Data!B5:B64,"<"&EDATE(A13,1)) | C13: =COUNTIFS(Cleaned_HR_Data!B5:B64,">="&A13,Cleaned_HR_Data!B5:B64,"<"&EDATE(A13,1)) | D13: 0 | E13: =SUMIFS(Cleaned_HR_Data!J5:J64,Cleaned_HR_Data!B5:B64,">="&A13,Cleaned_HR_Data!B5:B64,"<"&EDATE(A13,1))
A14: 45931 | B14: =COUNTIFS(Cleaned_HR_Data!B5:B64,">="&A14,Cleaned_HR_Data!B5:B64,"<"&EDATE(A14,1)) | C14: =COUNTIFS(Cleaned_HR_Data!B5:B64,">="&A14,Cleaned_HR_Data!B5:B64,"<"&EDATE(A14,1)) | D14: 0 | E14: =SUMIFS(Cleaned_HR_Data!J5:J64,Cleaned_HR_Data!B5:B64,">="&A14,Cleaned_HR_Data!B5:B64,"<"&EDATE(A14,1))
A15: 45962 | B15: =COUNTIFS(Cleaned_HR_Data!B5:B64,">="&A15,Cleaned_HR_Data!B5:B64,"<"&EDATE(A15,1)) | C15: =COUNTIFS(Cleaned_HR_Data!B5:B64,">="&A15,Cleaned_HR_Data!B5:B64,"<"&EDATE(A15,1)) | D15: 0 | E15: =SUMIFS(Cleaned_HR_Data!J5:J64,Cleaned_HR_Data!B5:B64,">="&A15,Cleaned_HR_Data!B5:B64,"<"&EDATE(A15,1))
A16: 45992 | B16: =COUNTIFS(Cleaned_HR_Data!B5:B64,">="&A16,Cleaned_HR_Data!B5:B64,"<"&EDATE(A16,1)) | C16: =COUNTIFS(Cleaned_HR_Data!B5:B64,">="&A16,Cleaned_HR_Data!B5:B64,"<"&EDATE(A16,1)) | D16: 0 | E16: =SUMIFS(Cleaned_HR_Data!J5:J64,Cleaned_HR_Data!B5:B64,">="&A16,Cleaned_HR_Data!B5:B64,"<"&EDATE(A16,1))
A17: 46023 | B17: =COUNTIFS(Cleaned_HR_Data!B5:B64,">="&A17,Cleaned_HR_Data!B5:B64,"<"&EDATE(A17,1)) | C17: =COUNTIFS(Cleaned_HR_Data!B5:B64,">="&A17,Cleaned_HR_Data!B5:B64,"<"&EDATE(A17,1)) | D17: 0 | E17: =SUMIFS(Cleaned_HR_Data!J5:J64,Cleaned_HR_Data!B5:B64,">="&A17,Cleaned_HR_Data!B5:B64,"<"&EDATE(A17,1))
A18: 46054 | B18: =COUNTIFS(Cleaned_HR_Data!B5:B64,">="&A18,Cleaned_HR_Data!B5:B64,"<"&EDATE(A18,1)) | C18: =COUNTIFS(Cleaned_HR_Data!B5:B64,">="&A18,Cleaned_HR_Data!B5:B64,"<"&EDATE(A18,1)) | D18: 0 | E18: =SUMIFS(Cleaned_HR_Data!J5:J64,Cleaned_HR_Data!B5:B64,">="&A18,Cleaned_HR_Data!B5:B64,"<"&EDATE(A18,1))
A19: 46082 | B19: =COUNTIFS(Cleaned_HR_Data!B5:B64,">="&A19,Cleaned_HR_Data!B5:B64,"<"&EDATE(A19,1)) | C19: =COUNTIFS(Cleaned_HR_Data!B5:B64,">="&A19,Cleaned_HR_Data!B5:B64,"<"&EDATE(A19,1)) | D19: 0 | E19: =SUMIFS(Cleaned_HR_Data!J5:J64,Cleaned_HR_Data!B5:B64,">="&A19,Cleaned_HR_Data!B5:B64,"<"&EDATE(A19,1))
A20: 46113 | B20: =COUNTIFS(Cleaned_HR_Data!B5:B64,">="&A20,Cleaned_HR_Data!B5:B64,"<"&EDATE(A20,1)) | C20: =COUNTIFS(Cleaned_HR_Data!B5:B64,">="&A20,Cleaned_HR_Data!B5:B64,"<"&EDATE(A20,1)) | D20: 0 | E20: =SUMIFS(Cleaned_HR_Data!J5:J64,Cleaned_HR_Data!B5:B64,">="&A20,Cleaned_HR_Data!B5:B64,"<"&EDATE(A20,1))
A21: 46143 | B21: =COUNTIFS(Cleaned_HR_Data!B5:B64,">="&A21,Cleaned_HR_Data!B5:B64,"<"&EDATE(A21,1)) | C21: =COUNTIFS(Cleaned_HR_Data!B5:B64,">="&A21,Cleaned_HR_Data!B5:B64,"<"&EDATE(A21,1)) | D21: 0 | E21: =SUMIFS(Cleaned_HR_Data!J5:J64,Cleaned_HR_Data!B5:B64,">="&A21,Cleaned_HR_Data!B5:B64,"<"&EDATE(A21,1))
A22: 46174 | B22: =COUNTIFS(Cleaned_HR_Data!B5:B64,">="&A22,Cleaned_HR_Data!B5:B64,"<"&EDATE(A22,1)) | C22: =COUNTIFS(Cleaned_HR_Data!B5:B64,">="&A22,Cleaned_HR_Data!B5:B64,"<"&EDATE(A22,1)) | D22: 0 | E22: =SUMIFS(Cleaned_HR_Data!J5:J64,Cleaned_HR_Data!B5:B64,">="&A22,Cleaned_HR_Data!B5:B64,"<"&EDATE(A22,1))

Sheet HR_KPI
A1: HR KPI
A4: KPI | B4: Value | C4: Description
A5: Total Employees | B5: =COUNTA(Cleaned_HR_Data!A5:A64) | C5: Number of employees
A6: Average Age | B6: =AVERAGE(Cleaned_HR_Data!D5:D64) | C6: Average employee age
A7: Average Experience (Years) | B7: =AVERAGE(Cleaned_HR_Data!I5:I64) | C7: Average experience
A8: Average Monthly Salary | B8: =AVERAGE(Cleaned_HR_Data!J5:J64) | C8: Average salary
A9: Total Monthly Salary Cost | B9: =SUM(Cleaned_HR_Data!J5:J64) | C9: Total salary cost
A10: Attrition Count | B10: =COUNTIF(Cleaned_HR_Data!M5:M64,"Yes") | C10: Attrition records
A11: Attrition Rate (%) | B11: =COUNTIF(Cleaned_HR_Data!M5:M64,"Yes")/COUNTA(Cleaned_HR_Data!A5:A64)*100 | C11: Attrition / total employees

Sheet Pivot_Department
A1: Pivot Department
A4: Department | B4: Employee_Count | C4: Average_Salary | D4: Total_Salary | E4: Average_Experience | F4: Attrition_Count | G4: Attrition_Rate_%
A5: ='Department_Analysis'!A5 | B5: ='Department_Analysis'!B5 | C5: ='Department_Analysis'!C5 | D5: ='Department_Analysis'!D5 | E5: ='Department_Analysis'!E5 | F5: ='Department_Analysis'!F5 | G5: ='Department_Analysis'!G5
A6: ='Department_Analysis'!A6 | B6: ='Department_Analysis'!B6 | C6: ='Department_Analysis'!C6 | D6: ='Department_Analysis'!D6 | E6: ='Department_Analysis'!E6 | F6: ='Department_Analysis'!F6 | G6: ='Department_Analysis'!G6
A7: ='Department_Analysis'!A7 | B7: ='Department_Analysis'!B7 | C7: ='Department_Analysis'!C7 | D7: ='Department_Analysis'!D7 | E7: ='Department_Analysis'!E7 | F7: ='Department_Analysis'!F7 | G7: ='Department_Analysis'!G7
A8: ='Department_Analysis'!A8 | B8: ='Department_Analysis'!B8 | C8: ='Department_Analysis'!C8 | D8: ='Department_Analysis'!D8 | E8: ='Department_Analysis'!E8 | F8: ='Department_Analysis'!F8 | G8: ='Department_Analysis'!G8
A9: ='Department_Analysis'!A9 | B9: ='Department_Analysis'!B9 | C9: ='Department_Analysis'!C9 | D9: ='Department_Analysis'!D9 | E9: ='Department_Analysis'!E9 | F9: ='Department_Analysis'!F9 | G9: ='Department_Analysis'!G9
A10: ='Department_Analysis'!A10 | B10: ='Department_Analysis'!B10 | C10: ='Department_Analysis'!C10 | D10: ='Department_Analysis'!D10 | E10: ='Department_Analysis'!E10 | F10: ='Department_Analysis'!F10 | G10: ='Department_Analysis'!G10

Sheet Pivot_Role
A1: Pivot Role
A4: Job_Role | B4: Employee_Count | C4: Average_Salary | D4: Total_Salary | E4: Average_Experience
A5: ='Job_Role_Analysis'!A5 | B5: ='Job_Role_Analysis'!B5 | C5: ='Job_Role_Analysis'!C5 | D5: ='Job_Role_Analysis'!D5 | E5: ='Job_Role_Analysis'!E5
A6: ='Job_Role_Analysis'!A6 | B6: ='Job_Role_Analysis'!B6 | C6: ='Job_Role_Analysis'!C6 | D6: ='Job_Role_Analysis'!D6 | E6: ='Job_Role_Analysis'!E6
A7: ='Job_Role_Analysis'!A7 | B7: ='Job_Role_Analysis'!B7 | C7: ='Job_Role_Analysis'!C7 | D7: ='Job_Role_Analysis'!D7 | E7: ='Job_Role_Analysis'!E7
A8: ='Job_Role_Analysis'!A8 | B8: ='Job_Role_Analysis'!B8 | C8: ='Job_Role_Analysis'!C8 | D8: ='Job_Role_Analysis'!D8 | E8: ='Job_Role_Analysis'!E8
A9: ='Job_Role_Analysis'!A9 | B9: ='Job_Role_Analysis'!B9 | C9: ='Job_Role_Analysis'!C9 | D9: ='Job_Role_Analysis'!D9 | E9: ='Job_Role_Analysis'!E9
A10: ='Job_Role_Analysis'!A10 | B10: ='Job_Role_Analysis'!B10 | C10: ='Job_Role_Analysis'!C10 | D10: ='Job_Role_Analysis'!D10 | E10: ='Job_Role_Analysis'!E10

Sheet Chart_Data
A1: Chart Data
A4: Department | B4: Employee_Count | C4: Average_Salary | D4: Attrition_Count
A5: Sales | B5: ='Department_Analysis'!B5 | C5: ='Department_Analysis'!C5 | D5: ='Department_Analysis'!F5
A6: Finance | B6: ='Department_Analysis'!B6 | C6: ='Department_Analysis'!C6 | D6: ='Department_Analysis'!F6
A7: HR | B7: ='Department_Analysis'!B7 | C7: ='Department_Analysis'!C7 | D7: ='Department_Analysis'!F7
A8: IT | B8: ='Department_Analysis'!B8 | C8: ='Department_Analysis'!C8 | D8: ='Department_Analysis'!F8
A9: Marketing | B9: ='Department_Analysis'!B9 | C9: ='Department_Analysis'!C9 | D9: ='Department_Analysis'!F9
A10: Operations | B10: ='Department_Analysis'!B10 | C10: ='Department_Analysis'!C10 | D10: ='Department_Analysis'!F10

Sheet Charts
A1: HR Analytics Charts

Sheet HR_Insights
A1: HR Business Insights
A4: Insight Area | B4: Observation | C4: Business Interpretation
A5: Workforce Size | B5: Review total employee count | C5: Understand workforce scale
A6: Department | B6: Compare employee counts | C6: Understand workforce distribution
A7: Salary | B7: Compare salary metrics by department | C7: Understand salary cost distribution
A8: Experience | B8: Compare average experience | C8: Understand workforce experience mix
A9: Attrition | B9: Review attrition count and rate | C9: Identify areas for further HR review
A10: Monthly Trend | B10: Review joining records over time | C10: Understand workforce changes

Sheet Final_HR_Analysis
A1: Final HR Analysis
A4: Section | B4: Key Measure / Task
A5: Data Quality | B5: Review missing, duplicate, inconsistent and invalid records
A6: Workforce | B6: Total employees, age and experience
A7: Department | B7: Employee count, salary, experience and attrition
A8: Job Role | B8: Employee count, salary and experience
A9: Salary | B9: Average, minimum, maximum and total salary
A10: Attrition | B10: Attrition count and attrition rate
A11: Monthly | B11: Joining records over time
A12: KPI | B12: Core HR performance indicators
A13: Visualisation | B13: Workforce, salary and attrition charts
A14: Business Insights | B14: Interpret results using cleaned data
